{"time":"2024-09-19 22:42:19","level":"ERROR","module":"__init__","method":"global_exception_logger","line":20,"path":"\/opt\/anaconda3\/lib\/python3.12\/site-packages\/anaconda_navigator\/utils\/logs\/__init__.py","message":"'bytes' object has no attribute 'copy'","exception":"Traceback (most recent call last):\n  File \"\/opt\/anaconda3\/lib\/python3.12\/site-packages\/anaconda_navigator\/api\/anaconda_api.py\", line 308, in _conda_info_processed\n    processed_info = self._process_conda_info(info)\n                     ^^^^^^^^^^^^^^^^^^^^^^^^^^^^^^\n  File \"\/opt\/anaconda3\/lib\/python3.12\/site-packages\/anaconda_navigator\/api\/anaconda_api.py\", line 357, in _process_conda_info\n    processed_info = info.copy()\n                     ^^^^^^^^^\nAttributeError: 'bytes' object has no attribute 'copy'"}
